Traceback (most recent call last):
  File "/data/data/com.termux/files/home/projects/Bubbles-payload/funpumper/funpumper_ws.py", line 22, in <module>
    asyncio.run(listen_mints())
  File "/data/data/com.termux/files/usr/lib/python3.12/asyncio/runners.py", line 195, in run
    return runner.run(main)
           ^^^^^^^^^^^^^^^^
  File "/data/data/com.termux/files/usr/lib/python3.12/asyncio/runners.py", line 118, in run
    return self._loop.run_until_complete(task)
           ^^^^^^^^^^^^^^^^^^^^^^^^^^^^^^^^^^^
  File "/data/data/com.termux/files/usr/lib/python3.12/asyncio/base_events.py", line 691, in run_until_complete
    return future.result()
           ^^^^^^^^^^^^^^^
  File "/data/data/com.termux/files/home/projects/Bubbles-payload/funpumper/funpumper_ws.py", line 10, in listen_mints
    async with connect(WS_URL) as websocket:
               ^^^^^^^^^^^^^^^
  File "/data/data/com.termux/files/usr/lib/python3.12/site-packages/websockets/asyncio/client.py", line 587, in __aenter__
    return await self
           ^^^^^^^^^^
  File "/data/data/com.termux/files/usr/lib/python3.12/site-packages/websockets/asyncio/client.py", line 541, in __await_impl__
    self.connection = await self.create_connection()
                      ^^^^^^^^^^^^^^^^^^^^^^^^^^^^^^
  File "/data/data/com.termux/files/usr/lib/python3.12/site-packages/websockets/asyncio/client.py", line 467, in create_connection
    _, connection = await loop.create_connection(factory, **kwargs)
                    ^^^^^^^^^^^^^^^^^^^^^^^^^^^^^^^^^^^^^^^^^^^^^^^
  File "/data/data/com.termux/files/usr/lib/python3.12/asyncio/base_events.py", line 1083, in create_connection
    infos = await self._ensure_resolved(
            ^^^^^^^^^^^^^^^^^^^^^^^^^^^^
  File "/data/data/com.termux/files/usr/lib/python3.12/asyncio/base_events.py", line 1466, in _ensure_resolved
    return await loop.getaddrinfo(host, port, family=family, type=type,
           ^^^^^^^^^^^^^^^^^^^^^^^^^^^^^^^^^^^^^^^^^^^^^^^^^^^^^^^^^^^^
  File "/data/data/com.termux/files/usr/lib/python3.12/asyncio/base_events.py", line 905, in getaddrinfo
    return await self.run_in_executor(
           ^^^^^^^^^^^^^^^^^^^^^^^^^^^
  File "/data/data/com.termux/files/usr/lib/python3.12/concurrent/futures/thread.py", line 59, in run
    result = self.fn(*self.args, **self.kwargs)
             ^^^^^^^^^^^^^^^^^^^^^^^^^^^^^^^^^^
  File "/data/data/com.termux/files/usr/lib/python3.12/socket.py", line 978, in getaddrinfo
    for res in _socket.getaddrinfo(host, port, family, type, proto, flags):
               ^^^^^^^^^^^^^^^^^^^^^^^^^^^^^^^^^^^^^^^^^^^^^^^^^^^^^^^^^^^
socket.gaierror: [Errno 7] No address associated with hostname
Traceback (most recent call last):
  File "/data/data/com.termux/files/home/projects/Bubbles-payload/funpumper/funpumper_ws.py", line 22, in <module>
    asyncio.run(listen_mints())
  File "/data/data/com.termux/files/usr/lib/python3.12/asyncio/runners.py", line 195, in run
    return runner.run(main)
           ^^^^^^^^^^^^^^^^
  File "/data/data/com.termux/files/usr/lib/python3.12/asyncio/runners.py", line 118, in run
    return self._loop.run_until_complete(task)
           ^^^^^^^^^^^^^^^^^^^^^^^^^^^^^^^^^^^
  File "/data/data/com.termux/files/usr/lib/python3.12/asyncio/base_events.py", line 691, in run_until_complete
    return future.result()
           ^^^^^^^^^^^^^^^
  File "/data/data/com.termux/files/home/projects/Bubbles-payload/funpumper/funpumper_ws.py", line 10, in listen_mints
    async with connect(WS_URL) as websocket:
               ^^^^^^^^^^^^^^^
  File "/data/data/com.termux/files/usr/lib/python3.12/site-packages/websockets/asyncio/client.py", line 587, in __aenter__
    return await self
           ^^^^^^^^^^
  File "/data/data/com.termux/files/usr/lib/python3.12/site-packages/websockets/asyncio/client.py", line 541, in __await_impl__
    self.connection = await self.create_connection()
                      ^^^^^^^^^^^^^^^^^^^^^^^^^^^^^^
  File "/data/data/com.termux/files/usr/lib/python3.12/site-packages/websockets/asyncio/client.py", line 467, in create_connection
    _, connection = await loop.create_connection(factory, **kwargs)
                    ^^^^^^^^^^^^^^^^^^^^^^^^^^^^^^^^^^^^^^^^^^^^^^^
  File "/data/data/com.termux/files/usr/lib/python3.12/asyncio/base_events.py", line 1083, in create_connection
    infos = await self._ensure_resolved(
            ^^^^^^^^^^^^^^^^^^^^^^^^^^^^
  File "/data/data/com.termux/files/usr/lib/python3.12/asyncio/base_events.py", line 1466, in _ensure_resolved
    return await loop.getaddrinfo(host, port, family=family, type=type,
           ^^^^^^^^^^^^^^^^^^^^^^^^^^^^^^^^^^^^^^^^^^^^^^^^^^^^^^^^^^^^
  File "/data/data/com.termux/files/usr/lib/python3.12/asyncio/base_events.py", line 905, in getaddrinfo
    return await self.run_in_executor(
           ^^^^^^^^^^^^^^^^^^^^^^^^^^^
  File "/data/data/com.termux/files/usr/lib/python3.12/concurrent/futures/thread.py", line 59, in run
    result = self.fn(*self.args, **self.kwargs)
             ^^^^^^^^^^^^^^^^^^^^^^^^^^^^^^^^^^
  File "/data/data/com.termux/files/usr/lib/python3.12/socket.py", line 978, in getaddrinfo
    for res in _socket.getaddrinfo(host, port, family, type, proto, flags):
               ^^^^^^^^^^^^^^^^^^^^^^^^^^^^^^^^^^^^^^^^^^^^^^^^^^^^^^^^^^^
socket.gaierror: [Errno 7] No address associated with hostname
Traceback (most recent call last):
  File "/data/data/com.termux/files/home/projects/Bubbles-payload/funpumper/funpumper_ws.py", line 22, in <module>
    asyncio.run(listen_mints())
  File "/data/data/com.termux/files/usr/lib/python3.12/asyncio/runners.py", line 195, in run
    return runner.run(main)
           ^^^^^^^^^^^^^^^^
  File "/data/data/com.termux/files/usr/lib/python3.12/asyncio/runners.py", line 118, in run
    return self._loop.run_until_complete(task)
           ^^^^^^^^^^^^^^^^^^^^^^^^^^^^^^^^^^^
  File "/data/data/com.termux/files/usr/lib/python3.12/asyncio/base_events.py", line 691, in run_until_complete
    return future.result()
           ^^^^^^^^^^^^^^^
  File "/data/data/com.termux/files/home/projects/Bubbles-payload/funpumper/funpumper_ws.py", line 10, in listen_mints
    async with connect(WS_URL) as websocket:
               ^^^^^^^^^^^^^^^
  File "/data/data/com.termux/files/usr/lib/python3.12/site-packages/websockets/asyncio/client.py", line 587, in __aenter__
    return await self
           ^^^^^^^^^^
  File "/data/data/com.termux/files/usr/lib/python3.12/site-packages/websockets/asyncio/client.py", line 541, in __await_impl__
    self.connection = await self.create_connection()
                      ^^^^^^^^^^^^^^^^^^^^^^^^^^^^^^
  File "/data/data/com.termux/files/usr/lib/python3.12/site-packages/websockets/asyncio/client.py", line 467, in create_connection
    _, connection = await loop.create_connection(factory, **kwargs)
                    ^^^^^^^^^^^^^^^^^^^^^^^^^^^^^^^^^^^^^^^^^^^^^^^
  File "/data/data/com.termux/files/usr/lib/python3.12/asyncio/base_events.py", line 1083, in create_connection
    infos = await self._ensure_resolved(
            ^^^^^^^^^^^^^^^^^^^^^^^^^^^^
  File "/data/data/com.termux/files/usr/lib/python3.12/asyncio/base_events.py", line 1466, in _ensure_resolved
    return await loop.getaddrinfo(host, port, family=family, type=type,
           ^^^^^^^^^^^^^^^^^^^^^^^^^^^^^^^^^^^^^^^^^^^^^^^^^^^^^^^^^^^^
  File "/data/data/com.termux/files/usr/lib/python3.12/asyncio/base_events.py", line 905, in getaddrinfo
    return await self.run_in_executor(
           ^^^^^^^^^^^^^^^^^^^^^^^^^^^
  File "/data/data/com.termux/files/usr/lib/python3.12/concurrent/futures/thread.py", line 59, in run
    result = self.fn(*self.args, **self.kwargs)
             ^^^^^^^^^^^^^^^^^^^^^^^^^^^^^^^^^^
  File "/data/data/com.termux/files/usr/lib/python3.12/socket.py", line 978, in getaddrinfo
    for res in _socket.getaddrinfo(host, port, family, type, proto, flags):
               ^^^^^^^^^^^^^^^^^^^^^^^^^^^^^^^^^^^^^^^^^^^^^^^^^^^^^^^^^^^
socket.gaierror: [Errno 7] No address associated with hostname
Traceback (most recent call last):
  File "/data/data/com.termux/files/home/projects/Bubbles-payload/funpumper/funpumper_ws.py", line 22, in <module>
    asyncio.run(listen_mints())
  File "/data/data/com.termux/files/usr/lib/python3.12/asyncio/runners.py", line 195, in run
    return runner.run(main)
           ^^^^^^^^^^^^^^^^
  File "/data/data/com.termux/files/usr/lib/python3.12/asyncio/runners.py", line 118, in run
    return self._loop.run_until_complete(task)
           ^^^^^^^^^^^^^^^^^^^^^^^^^^^^^^^^^^^
  File "/data/data/com.termux/files/usr/lib/python3.12/asyncio/base_events.py", line 691, in run_until_complete
    return future.result()
           ^^^^^^^^^^^^^^^
  File "/data/data/com.termux/files/home/projects/Bubbles-payload/funpumper/funpumper_ws.py", line 10, in listen_mints
    async with connect(WS_URL) as websocket:
               ^^^^^^^^^^^^^^^
  File "/data/data/com.termux/files/usr/lib/python3.12/site-packages/websockets/asyncio/client.py", line 587, in __aenter__
    return await self
           ^^^^^^^^^^
  File "/data/data/com.termux/files/usr/lib/python3.12/site-packages/websockets/asyncio/client.py", line 541, in __await_impl__
    self.connection = await self.create_connection()
                      ^^^^^^^^^^^^^^^^^^^^^^^^^^^^^^
  File "/data/data/com.termux/files/usr/lib/python3.12/site-packages/websockets/asyncio/client.py", line 467, in create_connection
    _, connection = await loop.create_connection(factory, **kwargs)
                    ^^^^^^^^^^^^^^^^^^^^^^^^^^^^^^^^^^^^^^^^^^^^^^^
  File "/data/data/com.termux/files/usr/lib/python3.12/asyncio/base_events.py", line 1083, in create_connection
    infos = await self._ensure_resolved(
            ^^^^^^^^^^^^^^^^^^^^^^^^^^^^
  File "/data/data/com.termux/files/usr/lib/python3.12/asyncio/base_events.py", line 1466, in _ensure_resolved
    return await loop.getaddrinfo(host, port, family=family, type=type,
           ^^^^^^^^^^^^^^^^^^^^^^^^^^^^^^^^^^^^^^^^^^^^^^^^^^^^^^^^^^^^
  File "/data/data/com.termux/files/usr/lib/python3.12/asyncio/base_events.py", line 905, in getaddrinfo
    return await self.run_in_executor(
           ^^^^^^^^^^^^^^^^^^^^^^^^^^^
  File "/data/data/com.termux/files/usr/lib/python3.12/concurrent/futures/thread.py", line 59, in run
    result = self.fn(*self.args, **self.kwargs)
             ^^^^^^^^^^^^^^^^^^^^^^^^^^^^^^^^^^
  File "/data/data/com.termux/files/usr/lib/python3.12/socket.py", line 978, in getaddrinfo
    for res in _socket.getaddrinfo(host, port, family, type, proto, flags):
               ^^^^^^^^^^^^^^^^^^^^^^^^^^^^^^^^^^^^^^^^^^^^^^^^^^^^^^^^^^^
socket.gaierror: [Errno 7] No address associated with hostname
Traceback (most recent call last):
  File "/data/data/com.termux/files/home/projects/Bubbles-payload/funpumper/funpumper_ws.py", line 22, in <module>
    asyncio.run(listen_mints())
  File "/data/data/com.termux/files/usr/lib/python3.12/asyncio/runners.py", line 195, in run
    return runner.run(main)
           ^^^^^^^^^^^^^^^^
  File "/data/data/com.termux/files/usr/lib/python3.12/asyncio/runners.py", line 118, in run
    return self._loop.run_until_complete(task)
           ^^^^^^^^^^^^^^^^^^^^^^^^^^^^^^^^^^^
  File "/data/data/com.termux/files/usr/lib/python3.12/asyncio/base_events.py", line 691, in run_until_complete
    return future.result()
           ^^^^^^^^^^^^^^^
  File "/data/data/com.termux/files/home/projects/Bubbles-payload/funpumper/funpumper_ws.py", line 10, in listen_mints
    async with connect(WS_URL) as websocket:
               ^^^^^^^^^^^^^^^
  File "/data/data/com.termux/files/usr/lib/python3.12/site-packages/websockets/asyncio/client.py", line 587, in __aenter__
    return await self
           ^^^^^^^^^^
  File "/data/data/com.termux/files/usr/lib/python3.12/site-packages/websockets/asyncio/client.py", line 541, in __await_impl__
    self.connection = await self.create_connection()
                      ^^^^^^^^^^^^^^^^^^^^^^^^^^^^^^
  File "/data/data/com.termux/files/usr/lib/python3.12/site-packages/websockets/asyncio/client.py", line 467, in create_connection
    _, connection = await loop.create_connection(factory, **kwargs)
                    ^^^^^^^^^^^^^^^^^^^^^^^^^^^^^^^^^^^^^^^^^^^^^^^
  File "/data/data/com.termux/files/usr/lib/python3.12/asyncio/base_events.py", line 1083, in create_connection
    infos = await self._ensure_resolved(
            ^^^^^^^^^^^^^^^^^^^^^^^^^^^^
  File "/data/data/com.termux/files/usr/lib/python3.12/asyncio/base_events.py", line 1466, in _ensure_resolved
    return await loop.getaddrinfo(host, port, family=family, type=type,
           ^^^^^^^^^^^^^^^^^^^^^^^^^^^^^^^^^^^^^^^^^^^^^^^^^^^^^^^^^^^^
  File "/data/data/com.termux/files/usr/lib/python3.12/asyncio/base_events.py", line 905, in getaddrinfo
    return await self.run_in_executor(
           ^^^^^^^^^^^^^^^^^^^^^^^^^^^
  File "/data/data/com.termux/files/usr/lib/python3.12/concurrent/futures/thread.py", line 59, in run
    result = self.fn(*self.args, **self.kwargs)
             ^^^^^^^^^^^^^^^^^^^^^^^^^^^^^^^^^^
  File "/data/data/com.termux/files/usr/lib/python3.12/socket.py", line 978, in getaddrinfo
    for res in _socket.getaddrinfo(host, port, family, type, proto, flags):
               ^^^^^^^^^^^^^^^^^^^^^^^^^^^^^^^^^^^^^^^^^^^^^^^^^^^^^^^^^^^
socket.gaierror: [Errno 7] No address associated with hostname
Traceback (most recent call last):
  File "/root/projects/Bubbles-payload/funpumper/funpumper_ws.py", line 120, in <module>
    run_ws_client()
  File "/root/projects/Bubbles-payload/funpumper/funpumper_ws.py", line 116, in run_ws_client
    asyncio.run(handle_messages())
  File "/usr/lib/python3.10/asyncio/runners.py", line 44, in run
    return loop.run_until_complete(main)
  File "/usr/lib/python3.10/asyncio/base_events.py", line 636, in run_until_complete
    self.run_forever()
  File "/usr/lib/python3.10/asyncio/base_events.py", line 603, in run_forever
    self._run_once()
  File "/usr/lib/python3.10/asyncio/base_events.py", line 1871, in _run_once
    event_list = self._selector.select(timeout)
  File "/usr/lib/python3.10/selectors.py", line 469, in select
    fd_event_list = self._selector.poll(timeout, max_ev)
KeyboardInterrupt
Traceback (most recent call last):
  File "/root/projects/Bubbles-payload/funpumper/funpumper_ws.py", line 120, in <module>
    run_ws_client()
  File "/root/projects/Bubbles-payload/funpumper/funpumper_ws.py", line 116, in run_ws_client
    asyncio.run(handle_messages())
  File "/usr/lib/python3.10/asyncio/runners.py", line 44, in run
    return loop.run_until_complete(main)
  File "/usr/lib/python3.10/asyncio/base_events.py", line 636, in run_until_complete
    self.run_forever()
  File "/usr/lib/python3.10/asyncio/base_events.py", line 603, in run_forever
    self._run_once()
  File "/usr/lib/python3.10/asyncio/base_events.py", line 1871, in _run_once
    event_list = self._selector.select(timeout)
  File "/usr/lib/python3.10/selectors.py", line 469, in select
    fd_event_list = self._selector.poll(timeout, max_ev)
KeyboardInterrupt
[2025-06-02T23:33:49.482822] [ERROR] gaierror(-5, 'No address associated with hostname')
[2025-06-02T23:36:10.973531] [ERROR] gaierror(-5, 'No address associated with hostname')
[2025-06-02T23:37:10.774727] [ERROR] gaierror(-5, 'No address associated with hostname')
[2025-06-02T23:39:42.224880] [ERROR] gaierror(-5, 'No address associated with hostname')
[2025-06-02T23:42:25.117418] [ERROR] gaierror(-5, 'No address associated with hostname')
[2025-06-02T23:43:32.265565] [ERROR] gaierror(-5, 'No address associated with hostname')
[2025-06-02T23:45:02.733662] [ERROR] gaierror(-5, 'No address associated with hostname')
[2025-06-02T23:54:39.905872] [ERROR] gaierror(-5, 'No address associated with hostname')
[2025-06-02T23:57:15.318804] [ERROR] gaierror(-5, 'No address associated with hostname')
[2025-06-03T00:00:31.222808] [ERROR] gaierror(-5, 'No address associated with hostname')
[2025-06-03T00:02:48.299731] [ERROR] gaierror(-5, 'No address associated with hostname')
[2025-06-03T00:04:47.595437] [ERROR] gaierror(-5, 'No address associated with hostname')
[2025-06-03T00:05:48.000434] [ERROR] gaierror(-5, 'No address associated with hostname')
[2025-06-03T00:07:45.136362] [ERROR] gaierror(-5, 'No address associated with hostname')
[2025-06-03T00:08:55.543763] [ERROR] gaierror(-5, 'No address associated with hostname')
[2025-06-03T00:10:12.217349] [ERROR] gaierror(-5, 'No address associated with hostname')
[2025-06-03T00:12:01.828724] [ERROR] gaierror(-5, 'No address associated with hostname')
[2025-06-03T00:12:52.530638] [ERROR] gaierror(-5, 'No address associated with hostname')
[2025-06-03T00:13:47.145409] [ERROR] gaierror(-5, 'No address associated with hostname')
[2025-06-03T00:14:30.938627] [ERROR] gaierror(-5, 'No address associated with hostname')
[2025-06-03T00:15:12.144844] [ERROR] gaierror(-5, 'No address associated with hostname')
[2025-06-03T00:15:53.075089] [ERROR] gaierror(-5, 'No address associated with hostname')
[2025-06-03T00:16:50.495127] [ERROR] gaierror(-5, 'No address associated with hostname')
[2025-06-03T00:17:25.693115] [ERROR] gaierror(-5, 'No address associated with hostname')
[2025-06-03T00:18:01.896818] [ERROR] gaierror(-5, 'No address associated with hostname')
[2025-06-03T00:18:33.782149] [ERROR] gaierror(-5, 'No address associated with hostname')
[2025-06-03T00:19:01.535848] [ERROR] gaierror(-5, 'No address associated with hostname')
[2025-06-03T00:19:45.203464] [ERROR] gaierror(-5, 'No address associated with hostname')
[2025-06-03T00:20:33.625390] [ERROR] gaierror(-5, 'No address associated with hostname')
[2025-06-03T00:22:02.531124] [ERROR] gaierror(-5, 'No address associated with hostname')
[2025-06-03T00:31:30.229076] [ERROR] gaierror(-5, 'No address associated with hostname')
[2025-06-03T00:56:09.541881] [ERROR] gaierror(-5, 'No address associated with hostname')
  File "/root/projects/Bubbles-payload/funpumper/funpumper_ws.py", line 27
    with open("common/logs/telemetry.log", "a") as fl:
IndentationError: expected an indented block after 'with' statement on line 26
  File "/root/projects/Bubbles-payload/funpumper/funpumper_ws.py", line 27
    with open("common/logs/telemetry.log", "a") as fl:
IndentationError: expected an indented block after 'with' statement on line 26
  File "/root/projects/Bubbles-payload/funpumper/funpumper_ws.py", line 27
    with open("common/logs/telemetry.log", "a") as fl:
IndentationError: expected an indented block after 'with' statement on line 26
  File "/root/projects/Bubbles-payload/funpumper/funpumper_ws.py", line 27
    with open("common/logs/telemetry.log", "a") as fl:
IndentationError: expected an indented block after 'with' statement on line 26
  File "/root/projects/Bubbles-payload/funpumper/funpumper_ws.py", line 27
    with open("common/logs/telemetry.log", "a") as fl:
IndentationError: expected an indented block after 'with' statement on line 26
